Workbook

Sheet Executive Summary
B1: DAWN RE ENTERPRISES CORP.
B2: E SUNRISE BLVD ASSEMBLAGE · COVERED LAND PLAY — EXECUTIVE SUMMARY
B3: Fort Lauderdale, FL 33304 · Galleria hard corner · five contiguous assets, plat block 49-42-36-12 · prepared 2026-07-21 · CONFIDENTIAL
B5: INCOME-BASED PRICE | E5: COVERED-LAND PRICE | H5: BLENDED IN-PLACE CAP | K5: LAND CONTROLLED
B6: ='Income Valuation'!C120 | E6: ='Assemblage'!C29 | H6: ='Assemblage'!C23 | K6: ='Assemblage'!C21
B7: what the combined cash flows support | E7: HBU: land value + assemblage premium | H7: income covers carry | K7: acres of E Sunrise frontage
B9: THE DEAL
B10: Assemble the entire E Sunrise Blvd frontage at the Galleria hard corner (~60,000 vehicles/day, across from the 31.5-ac Galleria
B11: redevelopment and the Live Local corridor). Five contiguous assets on one plat block. Strategy: buy/value each asset off the rent it
B12: produces, let the in-place income cover the carry, and control ~7+ acres for eventual Live Local high-density redevelopment. The
B13: redevelopment residual is negative today (AE flood zone, coastal hard costs), so the disciplined play is to HOLD income-covered land.
B14: Publix already validated the thesis — it paid land value ($679/SF building), not income value, to control its parcel.
B16: ASSET SCORECARD — 🟢 live links to each asset tab
B17: Asset | D17: Address / size | G17: Control cost | H17: In-place NOI | J17: Unlev IRR | K17: Lev IRR
B18: Shahidi Retail (Galleria Plaza) | D18: 2541–2595 E Sunrise · 26,272 SF retail | G18: ='Shahidi Retail'!C57 | H18: ='Shahidi Retail'!C122 | J18: ='Shahidi Retail'!C117 | K18: ='Shahidi Retail'!C120
B19: Publix + Starbucks | D19: 2501–2519 E Sunrise · 36,822 SF grocery + pad | G19: ='Publix & Starbucks'!C44 | H19: ='Publix & Starbucks'!C109 | J19: ='Publix & Starbucks'!C104 | K19: ='Publix & Starbucks'!C107
B20: Sunrise Plaza (Kar Luen) | D20: 2465–2485 E Sunrise · 25,105 SF retail | G20: ='Sunrise Plaza'!C47 | H20: ='Sunrise Plaza'!C112 | J20: ='Sunrise Plaza'!C107 | K20: ='Sunrise Plaza'!C110
B21: Galleria Corporate Centre | D21: 2455 E Sunrise · 168,807 SF office condo | G21: ='Office Condo'!I97 | H21: ='Office Condo'!C78 | J21: ='Office Condo'!C73 | K21: ='Office Condo'!C76
B22: 1040 Bayview (land) | D22: 1040 Bayview Dr · 2.39 ac · 259 units entitled | G22: ='Land'!E40 | H22: ='Land'!C47 | J22: ='Land'!C65 | K22: ='Land'!C68
B23: ASSEMBLAGE (pre-premium) | D23: 5 assets · ~7+ ac · 341,501 SF bldg | G23: ='Assemblage'!C17 | H23: ='Assemblage'!D17 | J23: ='Income Valuation'!C90 | K23: ='Income Valuation'!C92
B24: Portfolio IRR (unlev / lev) = consolidated cash-flow IRR at the income price (Income Valuation tab)
B26: CAPITAL, VALUATION & COVERED-LAND MATH
B27: ① Income-based price (assemblage cash flows) | C27: ='Income Valuation'!C120 | D27: direct cap on consolidated in-place NOI
B28: ② Sum of the parts (priced independently) | C28: ='Highest & Best Use'!C11 | D28: each component on its own
B29: ③ Covered-land / HBU price (assembled) | C29: ='Assemblage'!C29 | D29: sum of parts + assemblage premium
B30: Premium over income value (dirt + optionality) | C30: ='Income Valuation'!C122 | D30: ③ − ① = the land / Live Local option cost
B31: Office condo FULL BUY-OUT (both owners) | C31: ='Office Condo'!I97 | D31: Main St 57.4% + Intl Sunrise 42.6% + premium
B32: Land — fragmented vs. assembled (plottage) | C32: ='Highest & Best Use'!C39 | D32: assembled land worth this much more than the parts
B33: Summed control cost (pre-premium) | C33: ='Assemblage'!C17
B34: Total equity required (all assets, HBU) | C34: ='Assemblage'!C36
B35: Total in-place NOI | C35: ='Assemblage'!D17 | D35: covers debt service + taxes during hold
B36: Blended in-place cap | C36: ='Assemblage'!C23 | D36: covered-land ~3–5% range
B37: Total land assembled (SF) | C37: ='Assemblage'!F17
B38: Blended land basis ($/SF) | C38: ='Assemblage'!C22 | D38: vs. subject comps $228–255/SF
B39: Total land value | C39: ='Assemblage'!G17
B40: Redevelopment residual (Live Local) | C40: ='Land'!C78 | D40: NEGATIVE → hold, do not redevelop yet
B42: RETURNS AT THE INCOME PRICE & SCENARIO RANGE
B43: Portfolio unlevered / levered IRR (base) | C43: ='Income Valuation'!C92 | D43: levered; unlevered on Income Valuation tab
B44: Levered IRR — downside / base / upside | C44: ='Scenarios'!G22 | D44: ='Income Valuation'!C92 | E44: ='Scenarios'!G24 | F44: recession → plan → tailwind (see Scenarios tab)
B45: Avg cash-on-cash (base, levered) | C45: ='Income Valuation'!C96 | D45: current yield on equity
...

Sheet Assumptions
B1: ASSUMPTIONS — CONTROL PANEL
B2: The single input surface. GLOBAL drivers first, then a block per asset (price · rents · occupancy · OPERATING EXPENSES · caps · debt). Every blue cell drives the model by live link — change one and price, IRR, DSCR, and value all recalculate.
B4: GLOBAL — VALUATION & HOLD (→ Income Valuation)
B5: Driver | C5: Input | D5: Flag | E5: Drives / note
B6: Blended going-in cap (as-is) | C6: 0.065 | D6: 🔶 | E6: income price = as-is NOI ÷ this
B7: Blended stabilized / exit cap | C7: 0.0675 | D7: 🔶 | E7: reversion & stabilized value
B8: Target unlevered yield (DCF discount) | C8: 0.085 | D8: 🔶 | E8: DCF value; NPV hurdle
B9: Blended NOI growth | C9: 0.025 | D9: 🔶 | E9: reversion & sensitivities
B10: Hold period (yrs) | C10: 5 | D10: 🔶 | E10: exit year for all assets
B11: Cost of sale at exit | C11: 0.02 | D11: 🔶 | E11: net reversion
B12: GLOBAL — SENIOR FINANCING (→ Income Valuation)
B13: Driver | C13: Input | D13: Flag | E13: Drives / note
B14: Max senior LTV | C14: 0.6 | D14: 🔶 | E14: debt sizing constraint 1
B15: Min DSCR | C15: 1.3 | D15: 🔶 | E15: debt sizing constraint 2
B16: Min debt yield | C16: 0.085 | D16: 🔶 | E16: debt sizing constraint 3
B17: Senior rate | C17: 0.065 | D17: 🔶 | E17: debt service
B18: Amortization (yrs) | C18: 30 | D18: 🔶 | E18: mortgage constant
B19: GLOBAL — ACQUISITION COSTS (→ Income Valuation Sources & Uses)
B20: Driver | C20: Input | D20: Flag | E20: Drives / note
B21: Doc-stamp / transfer tax (% price) | C21: 0.007 | D21: 🔶 | E21: FL Broward $0.70/$100
B22: Title insurance (% price) | C22: 0.005 | D22: 🔶 | E22: closing cost
B23: Legal & due diligence (% price) | C23: 0.004 | D23: 🔶 | E23: closing cost
B24: Loan origination (% loan) | C24: 0.01 | D24: 🔶 | E24: financing cost → equity
B25: GLOBAL — ASSEMBLAGE PREMIUM (→ Assemblage / covered-land price)
B26: Driver | C26: Input | D26: Flag | E26: Drives / note
B27: Assemblage premium — low | C27: 0.15 | D27: 🔶 | E27: control-cost premium
B28: Assemblage premium — base | C28: 0.2 | D28: 🔶 | E28: headline covered-land price
B29: Assemblage premium — high | C29: 0.25 | D29: 🔶 | E29: aggressive case
B30: GLOBAL — LAND & REDEVELOPMENT (1040 Bayview) (→ Land tab)
B31: Driver | C31: Input | D31: Flag | E31: Drives / note
B32: Entitlement lift (% uplift post-Live Local approval) | C32: 0.3 | D32: 🔶 | E32: assembled land value bump once entitled
B33: Land value — low ($/SF) | C33: 64 | D33: 🔶 | E33: BCPA-implied floor
B34: Land value — base ($/SF) | C34: 125 | D34: 🔶 | E34: mid-block corridor
B35: Land value — high ($/SF) | C35: 200 | D35: 🔶 | E35: toward hard-corner comps
B36: Per entitled unit — low ($) | C36: 40000 | D36: 🔶 | E36: 259 units
B37: Per entitled unit — base ($) | C37: 55000 | D37: 🔶 | E37: entitled-land value
B38: Per entitled unit — high ($) | C38: 70000 | D38: 🔶 | E38: strong entitlement
B39: Achievable value per unit ($) | C39: 600000 | D39: 🔶 | E39: sellout / cap'd rental
B40: Hard cost ($/GBA SF) | C40: 500 | D40: 🔶 | E40: AE-zone coastal
B41: GBA per unit (SF) | C41: 950 | D41: 🔶 | E41: gross buildable/unit
...

Sheet Income Valuation
B1: ASSEMBLAGE — INCOME VALUATION (CONSOLIDATED CASH FLOWS)
B2: Combine every asset's cash flow → value the block on the income it produces (as-is + stabilized + DCF) → contrast with the covered-land / highest-and-best-use price. Portfolio returns run off consolidated cash flows.
B4: HOW THIS DIFFERS FROM THE HBU ASSEMBLAGE
B5: The Assemblage tab prices the block on a highest-and-best-use / covered-land basis (land value + assemblage premium to control every
B6: parcel). This tab prices the SAME block on the income it produces. Income-producing real estate is worth the rent it throws off — which
B7: is less than the land-control price. Returns are computed by consolidating the actual cash flows and running one IRR (not by averaging
B8: asset IRRs, which is mathematically invalid). Debt is sized to the lesser of LTV / DSCR / debt-yield, the way a lender underwrites.
B10: CONSOLIDATED CASH FLOW — 10-year annual (🟢 links to each asset tab)
B11: Year | D11: 1 | E11: 2 | F11: 3 | G11: 4 | H11: 5 | I11: 6 | J11: 7 | K11: 8 | L11: 9 | M11: 10
B12: Year ending | D12: Dec-2027 | E12: Dec-2028 | F12: Dec-2029 | G12: Dec-2030 | H12: Dec-2031 | I12: Dec-2032 | J12: Dec-2033 | K12: Dec-2034 | L12: Dec-2035 | M12: Dec-2036
B13: NET OPERATING INCOME by asset
B14: Shahidi Retail (Galleria Plaza) | D14: ='Shahidi Retail'!D100 | E14: ='Shahidi Retail'!E100 | F14: ='Shahidi Retail'!F100 | G14: ='Shahidi Retail'!G100 | H14: ='Shahidi Retail'!H100 | I14: ='Shahidi Retail'!I100 | J14: ='Shahidi Retail'!J100 | K14: ='Shahidi Retail'!K100 | ... M14: ='Shahidi Retail'!M100
B15: Publix + Starbucks | D15: ='Publix & Starbucks'!D87 | E15: ='Publix & Starbucks'!E87 | F15: ='Publix & Starbucks'!F87 | G15: ='Publix & Starbucks'!G87 | H15: ='Publix & Starbucks'!H87 | I15: ='Publix & Starbucks'!I87 | J15: ='Publix & Starbucks'!J87 | K15: ='Publix & Starbucks'!K87 | ... M15: ='Publix & Starbucks'!M87
B16: Sunrise Plaza (Kar Luen) | D16: ='Sunrise Plaza'!D90 | E16: ='Sunrise Plaza'!E90 | F16: ='Sunrise Plaza'!F90 | G16: ='Sunrise Plaza'!G90 | H16: ='Sunrise Plaza'!H90 | I16: ='Sunrise Plaza'!I90 | J16: ='Sunrise Plaza'!J90 | K16: ='Sunrise Plaza'!K90 | ... M16: ='Sunrise Plaza'!M90
B17: Galleria Corporate Centre (office) | D17: ='Office Condo'!D61 | E17: ='Office Condo'!E61 | F17: ='Office Condo'!F61 | G17: ='Office Condo'!G61 | H17: ='Office Condo'!H61 | I17: ='Office Condo'!I61 | J17: ='Office Condo'!J61 | K17: ='Office Condo'!K61 | ... M17: ='Office Condo'!M61
B18: 1040 Bayview (interim office) | D18: ='Land'!D58 | E18: ='Land'!E58 | F18: ='Land'!F58 | G18: ='Land'!G58 | H18: ='Land'!H58 | I18: ='Land'!I58 | J18: ='Land'!J58 | K18: ='Land'!K58 | ... M18: ='Land'!M58
B19: Consolidated NOI | D19: =SUM(D14:D18) | E19: =SUM(E14:E18) | F19: =SUM(F14:F18) | G19: =SUM(G14:G18) | H19: =SUM(H14:H18) | I19: =SUM(I14:I18) | J19: =SUM(J14:J18) | K19: =SUM(K14:K18) | ... M19: =SUM(M14:M18)
B20: Less: consolidated capital (reserves + leasing) | D20: =-('Shahidi Retail'!D104+'Publix & Starbucks'!D91+'Sunrise Plaza'!D94+'Office Condo'!D62) | E20: =-('Shahidi Retail'!E104+'Publix & Starbucks'!E91+'Sunrise Plaza'!E94+'Office Condo'!E62) | F20: =-('Shahidi Retail'!F104+'Publix & Starbucks'!F91+'Sunrise Plaza'!F94+'Office Condo'!F62) | G20: =-('Shahidi Retail'!G104+'Publix & Starbucks'!G91+'Sunrise Plaza'!G94+'Office Condo'!G62) | H20: =-('Shahidi Retail'!H104+'Publix & Starbucks'!H91+'Sunrise Plaza'!H94+'Office Condo'!H62) | I20: =-('Shahidi Retail'!I104+'Publix & Starbucks'!I91+'Sunrise Plaza'!I94+'Office Condo'!I62) | J20: =-('Shahidi Retail'!J104+'Publix & Starbucks'!J91+'Sunrise Plaza'!J94+'Office Condo'!J62) | K20: =-('Shahidi Retail'!K104+'Publix & Starbucks'!K91+'Sunrise Plaza'!K94+'Office Condo'!K62) | ... M20: =-('Shahidi Retail'!M104+'Publix & Starbucks'!M91+'Sunrise Plaza'!M94+'Office Condo'!M62)
B21: Consolidated unlevered operating CF | D21: =D19+D20 | E21: =E19+E20 | F21: =F19+F20 | G21: =G19+G20 | H21: =H19+H20 | I21: =I19+I20 | J21: =J19+J20 | K21: =K19+K20 | ... M21: =M19+M20
B22: Consolidated reversion (net sale, exit yr) | D22: ='Shahidi Retail'!D108+'Publix & Starbucks'!D95+'Sunrise Plaza'!D98+'Office Condo'!D66+'Land'!D59 | E22: ='Shahidi Retail'!E108+'Publix & Starbucks'!E95+'Sunrise Plaza'!E98+'Office Condo'!E66+'Land'!E59 | F22: ='Shahidi Retail'!F108+'Publix & Starbucks'!F95+'Sunrise Plaza'!F98+'Office Condo'!F66+'Land'!F59 | G22: ='Shahidi Retail'!G108+'Publix & Starbucks'!G95+'Sunrise Plaza'!G98+'Office Condo'!G66+'Land'!G59 | H22: ='Shahidi Retail'!H108+'Publix & Starbucks'!H95+'Sunrise Plaza'!H98+'Office Condo'!H66+'Land'!H59 | I22: ='Shahidi Retail'!I108+'Publix & Starbucks'!I95+'Sunrise Plaza'!I98+'Office Condo'!I66+'Land'!I59 | J22: ='Shahidi Retail'!J108+'Publix & Starbucks'!J95+'Sunrise Plaza'!J98+'Office Condo'!J66+'Land'!J59 | K22: ='Shahidi Retail'!K108+'Publix & Starbucks'!K95+'Sunrise Plaza'!K98+'Office Condo'!K66+'Land'!K59 | ... M22: ='Shahidi Retail'!M108+'Publix & Starbucks'!M95+'Sunrise Plaza'!M98+'Office Condo'!M66+'Land'!M59
B24: AS-IS vs. STABILIZED NOI (going-in vs. lease-up complete)
B25: Consolidated AS-IS in-place NOI | C25: ='Shahidi Retail'!C122+'Publix & Starbucks'!C110+'Sunrise Plaza'!C113+'Office Condo'!C79+'Land'!C47 | D25: current occupancy, no lease-up (going-in)
B26: Consolidated STABILIZED NOI (lease-up complete) | C26: ='Shahidi Retail'!C124+'Publix & Starbucks'!C112+'Sunrise Plaza'!C115+'Office Condo'!C81+'Land'!C47 | D26: post lease-up (Shahidi to 95%, Sunrise to 95%, office to 88%)
B27: Value creation (lease-up NOI gain) | C27: =C26-C25
B29: INCOME-VALUATION ASSUMPTIONS — 🟢 linked from the Assumptions control tab (adjust there)
B30: Blended going-in cap (as-is) | C30: ='Assumptions'!C6 | D30: 🟢 Assumptions tab
B31: Blended stabilized / exit cap | C31: ='Assumptions'!C7 | D31: 🟢 Assumptions tab
B32: Target unlevered yield (DCF discount) | C32: ='Assumptions'!C8 | D32: 🟢 Assumptions tab
B33: Blended NOI growth | C33: ='Assumptions'!C9 | D33: 🟢 Assumptions tab
B34: Hold period (yrs) | C34: ='Assumptions'!C10 | D34: 🟢 Assumptions tab
B35: Cost of sale at exit | C35: ='Assumptions'!C11 | D35: 🟢 Assumptions tab
B36: Doc-stamp / transfer tax (% price) | C36: ='Assumptions'!C21 | D36: 🟢 Assumptions tab
B37: Title insurance (% price) | C37: ='Assumptions'!C22 | D37: 🟢 Assumptions tab
B38: Legal & due diligence (% price) | C38: ='Assumptions'!C23 | D38: 🟢 Assumptions tab
B39: Loan origination fee (% loan) | C39: ='Assumptions'!C24 | D39: 🟢 Assumptions tab
B40: Max senior LTV | C40: ='Assumptions'!C14 | D40: 🟢 Assumptions tab
B41: Min DSCR (sizing constraint) | C41: ='Assumptions'!C15 | D41: 🟢 Assumptions tab
B42: Min debt yield (sizing constraint) | C42: ='Assumptions'!C16 | D42: 🟢 Assumptions tab
B43: Senior rate | C43: ='Assumptions'!C17 | D43: 🟢 Assumptions tab
B44: Amortization (yrs) | C44: ='Assumptions'!C18 | D44: 🟢 Assumptions tab
...

Sheet Scenarios
B1: SCENARIO ANALYSIS — DOWNSIDE / BASE / UPSIDE
B2: Acquisition held at the base income price; the business plan is stressed on NOI achievement, exit cap, and financing rate. Each case is a full consolidated cash flow with its own levered/unlevered return.
B4: SCENARIO DRIVERS — 🔵 blue inputs
B5: Scenario | C5: NOI achieved | D5: Exit cap | E5: Senior rate
B6: Downside | C6: 0.92 | D6: 0.0725 | E6: 0.0725
B7: Base | C7: 1 | D7: 0.0675 | E7: 0.065
B8: Upside | C8: 1.06 | D8: 0.0625 | E8: 0.06
B9: Base income price (fixed basis) | C9: ='Income Valuation'!C59 | E9: loan & equity held fixed; only the senior rate varies debt service across cases
B11: CONSOLIDATED CASH FLOW BY SCENARIO (unlevered & levered)
B12: Year | C12: 0/Acq | D12: 1 | E12: 2 | F12: 3 | G12: 4 | H12: 5 | I12: 6 | J12: 7 | K12: 8 | L12: 9 | M12: 10
B13: Downside — unlevered CF | C13: =-'Income Valuation'!C59*(1+'Income Valuation'!C49) | D13: =IF(1<='Income Valuation'!C34,'Income Valuation'!D21*C6,0)+IF(1='Income Valuation'!C34,('Income Valuation'!C52*C6*D7/D6),0) | E13: =IF(2<='Income Valuation'!C34,'Income Valuation'!E21*C6,0)+IF(2='Income Valuation'!C34,('Income Valuation'!C52*C6*D7/D6),0) | F13: =IF(3<='Income Valuation'!C34,'Income Valuation'!F21*C6,0)+IF(3='Income Valuation'!C34,('Income Valuation'!C52*C6*D7/D6),0) | G13: =IF(4<='Income Valuation'!C34,'Income Valuation'!G21*C6,0)+IF(4='Income Valuation'!C34,('Income Valuation'!C52*C6*D7/D6),0) | H13: =IF(5<='Income Valuation'!C34,'Income Valuation'!H21*C6,0)+IF(5='Income Valuation'!C34,('Income Valuation'!C52*C6*D7/D6),0) | I13: =IF(6<='Income Valuation'!C34,'Income Valuation'!I21*C6,0)+IF(6='Income Valuation'!C34,('Income Valuation'!C52*C6*D7/D6),0) | J13: =IF(7<='Income Valuation'!C34,'Income Valuation'!J21*C6,0)+IF(7='Income Valuation'!C34,('Income Valuation'!C52*C6*D7/D6),0) | K13: =IF(8<='Income Valuation'!C34,'Income Valuation'!K21*C6,0)+IF(8='Income Valuation'!C34,('Income Valuation'!C52*C6*D7/D6),0) | L13: =IF(9<='Income Valuation'!C34,'Income Valuation'!L21*C6,0)+IF(9='Income Valuation'!C34,('Income Valuation'!C52*C6*D7/D6),0) | M13: =IF(10<='Income Valuation'!C34,'Income Valuation'!M21*C6,0)+IF(10='Income Valuation'!C34,('Income Valuation'!C52*C6*D7/D6),0)
B14: Downside — levered CF | C14: =-('Income Valuation'!C59*(1+'Income Valuation'!C49)+'Income Valuation'!C39*'Income Valuation'!C65-'Income Valuation'!C65) | D14: =IF(1<='Income Valuation'!C34,'Income Valuation'!D21*C6-('Income Valuation'!C65*((E6/12)/(1-(1+(E6/12))^(-'Income Valuation'!C44*12))*12)),0)+IF(1='Income Valuation'!C34,('Income Valuation'!C52*C6*D7/D6)-('Income Valuation'!C65*(1+(E6/12))^(12*'Income Valuation'!C34)-(('Income Valuation'!C65*((E6/12)/(1-(1+(E6/12))^(-'Income Valuation'!C44*12))*12))/12)*((1+(E6/12))^(12*'Income Valuation'!C34)-1)/(E6/12)),0) | E14: =IF(2<='Income Valuation'!C34,'Income Valuation'!E21*C6-('Income Valuation'!C65*((E6/12)/(1-(1+(E6/12))^(-'Income Valuation'!C44*12))*12)),0)+IF(2='Income Valuation'!C34,('Income Valuation'!C52*C6*D7/D6)-('Income Valuation'!C65*(1+(E6/12))^(12*'Income Valuation'!C34)-(('Income Valuation'!C65*((E6/12)/(1-(1+(E6/12))^(-'Income Valuation'!C44*12))*12))/12)*((1+(E6/12))^(12*'Income Valuation'!C34)-1)/(E6/12)),0) | F14: =IF(3<='Income Valuation'!C34,'Income Valuation'!F21*C6-('Income Valuation'!C65*((E6/12)/(1-(1+(E6/12))^(-'Income Valuation'!C44*12))*12)),0)+IF(3='Income Valuation'!C34,('Income Valuation'!C52*C6*D7/D6)-('Income Valuation'!C65*(1+(E6/12))^(12*'Income Valuation'!C34)-(('Income Valuation'!C65*((E6/12)/(1-(1+(E6/12))^(-'Income Valuation'!C44*12))*12))/12)*((1+(E6/12))^(12*'Income Valuation'!C34)-1)/(E6/12)),0) | G14: =IF(4<='Income Valuation'!C34,'Income Valuation'!G21*C6-('Income Valuation'!C65*((E6/12)/(1-(1+(E6/12))^(-'Income Valuation'!C44*12))*12)),0)+IF(4='Income Valuation'!C34,('Income Valuation'!C52*C6*D7/D6)-('Income Valuation'!C65*(1+(E6/12))^(12*'Income Valuation'!C34)-(('Income Valuation'!C65*((E6/12)/(1-(1+(E6/12))^(-'Income Valuation'!C44*12))*12))/12)*((1+(E6/12))^(12*'Income Valuation'!C34)-1)/(E6/12)),0) | H14: =IF(5<='Income Valuation'!C34,'Income Valuation'!H21*C6-('Income Valuation'!C65*((E6/12)/(1-(1+(E6/12))^(-'Income Valuation'!C44*12))*12)),0)+IF(5='Income Valuation'!C34,('Income Valuation'!C52*C6*D7/D6)-('Income Valuation'!C65*(1+(E6/12))^(12*'Income Valuation'!C34)-(('Income Valuation'!C65*((E6/12)/(1-(1+(E6/12))^(-'Income Valuation'!C44*12))*12))/12)*((1+(E6/12))^(12*'Income Valuation'!C34)-1)/(E6/12)),0) | I14: =IF(6<='Income Valuation'!C34,'Income Valuation'!I21*C6-('Income Valuation'!C65*((E6/12)/(1-(1+(E6/12))^(-'Income Valuation'!C44*12))*12)),0)+IF(6='Income Valuation'!C34,('Income Valuation'!C52*C6*D7/D6)-('Income Valuation'!C65*(1+(E6/12))^(12*'Income Valuation'!C34)-(('Income Valuation'!C65*((E6/12)/(1-(1+(E6/12))^(-'Income Valuation'!C44*12))*12))/12)*((1+(E6/12))^(12*'Income Valuation'!C34)-1)/(E6/12)),0) | J14: =IF(7<='Income Valuation'!C34,'Income Valuation'!J21*C6-('Income Valuation'!C65*((E6/12)/(1-(1+(E6/12))^(-'Income Valuation'!C44*12))*12)),0)+IF(7='Income Valuation'!C34,('Income Valuation'!C52*C6*D7/D6)-('Income Valuation'!C65*(1+(E6/12))^(12*'Income Valuation'!C34)-(('Income Valuation'!C65*((E6/12)/(1-(1+(E6/12))^(-'Income Valuation'!C44*12))*12))/12)*((1+(E6/12))^(12*'Income Valuation'!C34)-1)/(E6/12)),0) | K14: =IF(8<='Income Valuation'!C34,'Income Valuation'!K21*C6-('Income Valuation'!C65*((E6/12)/(1-(1+(E6/12))^(-'Income Valuation'!C44*12))*12)),0)+IF(8='Income Valuation'!C34,('Income Valuation'!C52*C6*D7/D6)-('Income Valuation'!C65*(1+(E6/12))^(12*'Income Valuation'!C34)-(('Income Valuation'!C65*((E6/12)/(1-(1+(E6/12))^(-'Income Valuation'!C44*12))*12))/12)*((1+(E6/12))^(12*'Income Valuation'!C34)-1)/(E6/12)),0) | L14: =IF(9<='Income Valuation'!C34,'Income Valuation'!L21*C6-('Income Valuation'!C65*((E6/12)/(1-(1+(E6/12))^(-'Income Valuation'!C44*12))*12)),0)+IF(9='Income Valuation'!C34,('Income Valuation'!C52*C6*D7/D6)-('Income Valuation'!C65*(1+(E6/12))^(12*'Income Valuation'!C34)-(('Income Valuation'!C65*((E6/12)/(1-(1+(E6/12))^(-'Income Valuation'!C44*12))*12))/12)*((1+(E6/12))^(12*'Income Valuation'!C34)-1)/(E6/12)),0) | M14: =IF(10<='Income Valuation'!C34,'Income Valuation'!M21*C6-('Income Valuation'!C65*((E6/12)/(1-(1+(E6/12))^(-'Income Valuation'!C44*12))*12)),0)+IF(10='Income Valuation'!C34,('Income Valuation'!C52*C6*D7/D6)-('Income Valuation'!C65*(1+(E6/12))^(12*'Income Valuation'!C34)-(('Income Valuation'!C65*((E6/12)/(1-(1+(E6/12))^(-'Income Valuation'!C44*12))*12))/12)*((1+(E6/12))^(12*'Income Valuation'!C34)-1)/(E6/12)),0)
B15: Base — unlevered CF | C15: =-'Income Valuation'!C59*(1+'Income Valuation'!C49) | D15: =IF(1<='Income Valuation'!C34,'Income Valuation'!D21*C7,0)+IF(1='Income Valuation'!C34,('Income Valuation'!C52*C7*D7/D7),0) | E15: =IF(2<='Income Valuation'!C34,'Income Valuation'!E21*C7,0)+IF(2='Income Valuation'!C34,('Income Valuation'!C52*C7*D7/D7),0) | F15: =IF(3<='Income Valuation'!C34,'Income Valuation'!F21*C7,0)+IF(3='Income Valuation'!C34,('Income Valuation'!C52*C7*D7/D7),0) | G15: =IF(4<='Income Valuation'!C34,'Income Valuation'!G21*C7,0)+IF(4='Income Valuation'!C34,('Income Valuation'!C52*C7*D7/D7),0) | H15: =IF(5<='Income Valuation'!C34,'Income Valuation'!H21*C7,0)+IF(5='Income Valuation'!C34,('Income Valuation'!C52*C7*D7/D7),0) | I15: =IF(6<='Income Valuation'!C34,'Income Valuation'!I21*C7,0)+IF(6='Income Valuation'!C34,('Income Valuation'!C52*C7*D7/D7),0) | J15: =IF(7<='Income Valuation'!C34,'Income Valuation'!J21*C7,0)+IF(7='Income Valuation'!C34,('Income Valuation'!C52*C7*D7/D7),0) | K15: =IF(8<='Income Valuation'!C34,'Income Valuation'!K21*C7,0)+IF(8='Income Valuation'!C34,('Income Valuation'!C52*C7*D7/D7),0) | L15: =IF(9<='Income Valuation'!C34,'Income Valuation'!L21*C7,0)+IF(9='Income Valuation'!C34,('Income Valuation'!C52*C7*D7/D7),0) | M15: =IF(10<='Income Valuation'!C34,'Income Valuation'!M21*C7,0)+IF(10='Income Valuation'!C34,('Income Valuation'!C52*C7*D7/D7),0)
B16: Base — levered CF | C16: =-('Income Valuation'!C59*(1+'Income Valuation'!C49)+'Income Valuation'!C39*'Income Valuation'!C65-'Income Valuation'!C65) | D16: =IF(1<='Income Valuation'!C34,'Income Valuation'!D21*C7-('Income Valuation'!C65*((E7/12)/(1-(1+(E7/12))^(-'Income Valuation'!C44*12))*12)),0)+IF(1='Income Valuation'!C34,('Income Valuation'!C52*C7*D7/D7)-('Income Valuation'!C65*(1+(E7/12))^(12*'Income Valuation'!C34)-(('Income Valuation'!C65*((E7/12)/(1-(1+(E7/12))^(-'Income Valuation'!C44*12))*12))/12)*((1+(E7/12))^(12*'Income Valuation'!C34)-1)/(E7/12)),0) | E16: =IF(2<='Income Valuation'!C34,'Income Valuation'!E21*C7-('Income Valuation'!C65*((E7/12)/(1-(1+(E7/12))^(-'Income Valuation'!C44*12))*12)),0)+IF(2='Income Valuation'!C34,('Income Valuation'!C52*C7*D7/D7)-('Income Valuation'!C65*(1+(E7/12))^(12*'Income Valuation'!C34)-(('Income Valuation'!C65*((E7/12)/(1-(1+(E7/12))^(-'Income Valuation'!C44*12))*12))/12)*((1+(E7/12))^(12*'Income Valuation'!C34)-1)/(E7/12)),0) | F16: =IF(3<='Income Valuation'!C34,'Income Valuation'!F21*C7-('Income Valuation'!C65*((E7/12)/(1-(1+(E7/12))^(-'Income Valuation'!C44*12))*12)),0)+IF(3='Income Valuation'!C34,('Income Valuation'!C52*C7*D7/D7)-('Income Valuation'!C65*(1+(E7/12))^(12*'Income Valuation'!C34)-(('Income Valuation'!C65*((E7/12)/(1-(1+(E7/12))^(-'Income Valuation'!C44*12))*12))/12)*((1+(E7/12))^(12*'Income Valuation'!C34)-1)/(E7/12)),0) | G16: =IF(4<='Income Valuation'!C34,'Income Valuation'!G21*C7-('Income Valuation'!C65*((E7/12)/(1-(1+(E7/12))^(-'Income Valuation'!C44*12))*12)),0)+IF(4='Income Valuation'!C34,('Income Valuation'!C52*C7*D7/D7)-('Income Valuation'!C65*(1+(E7/12))^(12*'Income Valuation'!C34)-(('Income Valuation'!C65*((E7/12)/(1-(1+(E7/12))^(-'Income Valuation'!C44*12))*12))/12)*((1+(E7/12))^(12*'Income Valuation'!C34)-1)/(E7/12)),0) | H16: =IF(5<='Income Valuation'!C34,'Income Valuation'!H21*C7-('Income Valuation'!C65*((E7/12)/(1-(1+(E7/12))^(-'Income Valuation'!C44*12))*12)),0)+IF(5='Income Valuation'!C34,('Income Valuation'!C52*C7*D7/D7)-('Income Valuation'!C65*(1+(E7/12))^(12*'Income Valuation'!C34)-(('Income Valuation'!C65*((E7/12)/(1-(1+(E7/12))^(-'Income Valuation'!C44*12))*12))/12)*((1+(E7/12))^(12*'Income Valuation'!C34)-1)/(E7/12)),0) | I16: =IF(6<='Income Valuation'!C34,'Income Valuation'!I21*C7-('Income Valuation'!C65*((E7/12)/(1-(1+(E7/12))^(-'Income Valuation'!C44*12))*12)),0)+IF(6='Income Valuation'!C34,('Income Valuation'!C52*C7*D7/D7)-('Income Valuation'!C65*(1+(E7/12))^(12*'Income Valuation'!C34)-(('Income Valuation'!C65*((E7/12)/(1-(1+(E7/12))^(-'Income Valuation'!C44*12))*12))/12)*((1+(E7/12))^(12*'Income Valuation'!C34)-1)/(E7/12)),0) | J16: =IF(7<='Income Valuation'!C34,'Income Valuation'!J21*C7-('Income Valuation'!C65*((E7/12)/(1-(1+(E7/12))^(-'Income Valuation'!C44*12))*12)),0)+IF(7='Income Valuation'!C34,('Income Valuation'!C52*C7*D7/D7)-('Income Valuation'!C65*(1+(E7/12))^(12*'Income Valuation'!C34)-(('Income Valuation'!C65*((E7/12)/(1-(1+(E7/12))^(-'Income Valuation'!C44*12))*12))/12)*((1+(E7/12))^(12*'Income Valuation'!C34)-1)/(E7/12)),0) | K16: =IF(8<='Income Valuation'!C34,'Income Valuation'!K21*C7-('Income Valuation'!C65*((E7/12)/(1-(1+(E7/12))^(-'Income Valuation'!C44*12))*12)),0)+IF(8='Income Valuation'!C34,('Income Valuation'!C52*C7*D7/D7)-('Income Valuation'!C65*(1+(E7/12))^(12*'Income Valuation'!C34)-(('Income Valuation'!C65*((E7/12)/(1-(1+(E7/12))^(-'Income Valuation'!C44*12))*12))/12)*((1+(E7/12))^(12*'Income Valuation'!C34)-1)/(E7/12)),0) | L16: =IF(9<='Income Valuation'!C34,'Income Valuation'!L21*C7-('Income Valuation'!C65*((E7/12)/(1-(1+(E7/12))^(-'Income Valuation'!C44*12))*12)),0)+IF(9='Income Valuation'!C34,('Income Valuation'!C52*C7*D7/D7)-('Income Valuation'!C65*(1+(E7/12))^(12*'Income Valuation'!C34)-(('Income Valuation'!C65*((E7/12)/(1-(1+(E7/12))^(-'Income Valuation'!C44*12))*12))/12)*((1+(E7/12))^(12*'Income Valuation'!C34)-1)/(E7/12)),0) | M16: =IF(10<='Income Valuation'!C34,'Income Valuation'!M21*C7-('Income Valuation'!C65*((E7/12)/(1-(1+(E7/12))^(-'Income Valuation'!C44*12))*12)),0)+IF(10='Income Valuation'!C34,('Income Valuation'!C52*C7*D7/D7)-('Income Valuation'!C65*(1+(E7/12))^(12*'Income Valuation'!C34)-(('Income Valuation'!C65*((E7/12)/(1-(1+(E7/12))^(-'Income Valuation'!C44*12))*12))/12)*((1+(E7/12))^(12*'Income Valuation'!C34)-1)/(E7/12)),0)
B17: Upside — unlevered CF | C17: =-'Income Valuation'!C59*(1+'Income Valuation'!C49) | D17: =IF(1<='Income Valuation'!C34,'Income Valuation'!D21*C8,0)+IF(1='Income Valuation'!C34,('Income Valuation'!C52*C8*D7/D8),0) | E17: =IF(2<='Income Valuation'!C34,'Income Valuation'!E21*C8,0)+IF(2='Income Valuation'!C34,('Income Valuation'!C52*C8*D7/D8),0) | F17: =IF(3<='Income Valuation'!C34,'Income Valuation'!F21*C8,0)+IF(3='Income Valuation'!C34,('Income Valuation'!C52*C8*D7/D8),0) | G17: =IF(4<='Income Valuation'!C34,'Income Valuation'!G21*C8,0)+IF(4='Income Valuation'!C34,('Income Valuation'!C52*C8*D7/D8),0) | H17: =IF(5<='Income Valuation'!C34,'Income Valuation'!H21*C8,0)+IF(5='Income Valuation'!C34,('Income Valuation'!C52*C8*D7/D8),0) | I17: =IF(6<='Income Valuation'!C34,'Income Valuation'!I21*C8,0)+IF(6='Income Valuation'!C34,('Income Valuation'!C52*C8*D7/D8),0) | J17: =IF(7<='Income Valuation'!C34,'Income Valuation'!J21*C8,0)+IF(7='Income Valuation'!C34,('Income Valuation'!C52*C8*D7/D8),0) | K17: =IF(8<='Income Valuation'!C34,'Income Valuation'!K21*C8,0)+IF(8='Income Valuation'!C34,('Income Valuation'!C52*C8*D7/D8),0) | L17: =IF(9<='Income Valuation'!C34,'Income Valuation'!L21*C8,0)+IF(9='Income Valuation'!C34,('Income Valuation'!C52*C8*D7/D8),0) | M17: =IF(10<='Income Valuation'!C34,'Income Valuation'!M21*C8,0)+IF(10='Income Valuation'!C34,('Income Valuation'!C52*C8*D7/D8),0)
B18: Upside — levered CF | C18: =-('Income Valuation'!C59*(1+'Income Valuation'!C49)+'Income Valuation'!C39*'Income Valuation'!C65-'Income Valuation'!C65) | D18: =IF(1<='Income Valuation'!C34,'Income Valuation'!D21*C8-('Income Valuation'!C65*((E8/12)/(1-(1+(E8/12))^(-'Income Valuation'!C44*12))*12)),0)+IF(1='Income Valuation'!C34,('Income Valuation'!C52*C8*D7/D8)-('Income Valuation'!C65*(1+(E8/12))^(12*'Income Valuation'!C34)-(('Income Valuation'!C65*((E8/12)/(1-(1+(E8/12))^(-'Income Valuation'!C44*12))*12))/12)*((1+(E8/12))^(12*'Income Valuation'!C34)-1)/(E8/12)),0) | E18: =IF(2<='Income Valuation'!C34,'Income Valuation'!E21*C8-('Income Valuation'!C65*((E8/12)/(1-(1+(E8/12))^(-'Income Valuation'!C44*12))*12)),0)+IF(2='Income Valuation'!C34,('Income Valuation'!C52*C8*D7/D8)-('Income Valuation'!C65*(1+(E8/12))^(12*'Income Valuation'!C34)-(('Income Valuation'!C65*((E8/12)/(1-(1+(E8/12))^(-'Income Valuation'!C44*12))*12))/12)*((1+(E8/12))^(12*'Income Valuation'!C34)-1)/(E8/12)),0) | F18: =IF(3<='Income Valuation'!C34,'Income Valuation'!F21*C8-('Income Valuation'!C65*((E8/12)/(1-(1+(E8/12))^(-'Income Valuation'!C44*12))*12)),0)+IF(3='Income Valuation'!C34,('Income Valuation'!C52*C8*D7/D8)-('Income Valuation'!C65*(1+(E8/12))^(12*'Income Valuation'!C34)-(('Income Valuation'!C65*((E8/12)/(1-(1+(E8/12))^(-'Income Valuation'!C44*12))*12))/12)*((1+(E8/12))^(12*'Income Valuation'!C34)-1)/(E8/12)),0) | G18: =IF(4<='Income Valuation'!C34,'Income Valuation'!G21*C8-('Income Valuation'!C65*((E8/12)/(1-(1+(E8/12))^(-'Income Valuation'!C44*12))*12)),0)+IF(4='Income Valuation'!C34,('Income Valuation'!C52*C8*D7/D8)-('Income Valuation'!C65*(1+(E8/12))^(12*'Income Valuation'!C34)-(('Income Valuation'!C65*((E8/12)/(1-(1+(E8/12))^(-'Income Valuation'!C44*12))*12))/12)*((1+(E8/12))^(12*'Income Valuation'!C34)-1)/(E8/12)),0) | H18: =IF(5<='Income Valuation'!C34,'Income Valuation'!H21*C8-('Income Valuation'!C65*((E8/12)/(1-(1+(E8/12))^(-'Income Valuation'!C44*12))*12)),0)+IF(5='Income Valuation'!C34,('Income Valuation'!C52*C8*D7/D8)-('Income Valuation'!C65*(1+(E8/12))^(12*'Income Valuation'!C34)-(('Income Valuation'!C65*((E8/12)/(1-(1+(E8/12))^(-'Income Valuation'!C44*12))*12))/12)*((1+(E8/12))^(12*'Income Valuation'!C34)-1)/(E8/12)),0) | I18: =IF(6<='Income Valuation'!C34,'Income Valuation'!I21*C8-('Income Valuation'!C65*((E8/12)/(1-(1+(E8/12))^(-'Income Valuation'!C44*12))*12)),0)+IF(6='Income Valuation'!C34,('Income Valuation'!C52*C8*D7/D8)-('Income Valuation'!C65*(1+(E8/12))^(12*'Income Valuation'!C34)-(('Income Valuation'!C65*((E8/12)/(1-(1+(E8/12))^(-'Income Valuation'!C44*12))*12))/12)*((1+(E8/12))^(12*'Income Valuation'!C34)-1)/(E8/12)),0) | J18: =IF(7<='Income Valuation'!C34,'Income Valuation'!J21*C8-('Income Valuation'!C65*((E8/12)/(1-(1+(E8/12))^(-'Income Valuation'!C44*12))*12)),0)+IF(7='Income Valuation'!C34,('Income Valuation'!C52*C8*D7/D8)-('Income Valuation'!C65*(1+(E8/12))^(12*'Income Valuation'!C34)-(('Income Valuation'!C65*((E8/12)/(1-(1+(E8/12))^(-'Income Valuation'!C44*12))*12))/12)*((1+(E8/12))^(12*'Income Valuation'!C34)-1)/(E8/12)),0) | K18: =IF(8<='Income Valuation'!C34,'Income Valuation'!K21*C8-('Income Valuation'!C65*((E8/12)/(1-(1+(E8/12))^(-'Income Valuation'!C44*12))*12)),0)+IF(8='Income Valuation'!C34,('Income Valuation'!C52*C8*D7/D8)-('Income Valuation'!C65*(1+(E8/12))^(12*'Income Valuation'!C34)-(('Income Valuation'!C65*((E8/12)/(1-(1+(E8/12))^(-'Income Valuation'!C44*12))*12))/12)*((1+(E8/12))^(12*'Income Valuation'!C34)-1)/(E8/12)),0) | L18: =IF(9<='Income Valuation'!C34,'Income Valuation'!L21*C8-('Income Valuation'!C65*((E8/12)/(1-(1+(E8/12))^(-'Income Valuation'!C44*12))*12)),0)+IF(9='Income Valuation'!C34,('Income Valuation'!C52*C8*D7/D8)-('Income Valuation'!C65*(1+(E8/12))^(12*'Income Valuation'!C34)-(('Income Valuation'!C65*((E8/12)/(1-(1+(E8/12))^(-'Income Valuation'!C44*12))*12))/12)*((1+(E8/12))^(12*'Income Valuation'!C34)-1)/(E8/12)),0) | M18: =IF(10<='Income Valuation'!C34,'Income Valuation'!M21*C8-('Income Valuation'!C65*((E8/12)/(1-(1+(E8/12))^(-'Income Valuation'!C44*12))*12)),0)+IF(10='Income Valuation'!C34,('Income Valuation'!C52*C8*D7/D8)-('Income Valuation'!C65*(1+(E8/12))^(12*'Income Valuation'!C34)-(('Income Valuation'!C65*((E8/12)/(1-(1+(E8/12))^(-'Income Valuation'!C44*12))*12))/12)*((1+(E8/12))^(12*'Income Valuation'!C34)-1)/(E8/12)),0)
B20: SCENARIO SUMMARY — returns at the base income price
B21: Scenario | D21: Income value | F21: Unlev IRR | G21: Lev IRR | H21: Lev EM | I21: Yr-1 DSCR | J21: Avg CoC
B22: Downside | D22: ='Income Valuation'!C25*C6/'Income Valuation'!C30 | F22: =IRR(C13:M13) | G22: =IRR(C14:M14) | H22: =SUM(D14:M14)/('Income Valuation'!C59*(1+'Income Valuation'!C49)+'Income Valuation'!C39*'Income Valuation'!C65-'Income Valuation'!C65) | I22: ='Income Valuation'!C25*C6/('Income Valuation'!C65*((E6/12)/(1-(1+(E6/12))^(-'Income Valuation'!C44*12))*12)) | J22: =('Income Valuation'!C50*C6-'Income Valuation'!C34*('Income Valuation'!C65*((E6/12)/(1-(1+(E6/12))^(-'Income Valuation'!C44*12))*12)))/'Income Valuation'!C34/('Income Valuation'!C59*(1+'Income Valuation'!C49)+'Income Valuation'!C39*'Income Valuation'!C65-'Income Valuation'!C65)
B23: Base | D23: ='Income Valuation'!C25*C7/'Income Valuation'!C30 | F23: =IRR(C15:M15) | G23: =IRR(C16:M16) | H23: =SUM(D16:M16)/('Income Valuation'!C59*(1+'Income Valuation'!C49)+'Income Valuation'!C39*'Income Valuation'!C65-'Income Valuation'!C65) | I23: ='Income Valuation'!C25*C7/('Income Valuation'!C65*((E7/12)/(1-(1+(E7/12))^(-'Income Valuation'!C44*12))*12)) | J23: =('Income Valuation'!C50*C7-'Income Valuation'!C34*('Income Valuation'!C65*((E7/12)/(1-(1+(E7/12))^(-'Income Valuation'!C44*12))*12)))/'Income Valuation'!C34/('Income Valuation'!C59*(1+'Income Valuation'!C49)+'Income Valuation'!C39*'Income Valuation'!C65-'Income Valuation'!C65)
B24: Upside | D24: ='Income Valuation'!C25*C8/'Income Valuation'!C30 | F24: =IRR(C17:M17) | G24: =IRR(C18:M18) | H24: =SUM(D18:M18)/('Income Valuation'!C59*(1+'Income Valuation'!C49)+'Income Valuation'!C39*'Income Valuation'!C65-'Income Valuation'!C65) | I24: ='Income Valuation'!C25*C8/('Income Valuation'!C65*((E8/12)/(1-(1+(E8/12))^(-'Income Valuation'!C44*12))*12)) | J24: =('Income Valuation'!C50*C8-'Income Valuation'!C34*('Income Valuation'!C65*((E8/12)/(1-(1+(E8/12))^(-'Income Valuation'!C44*12))*12)))/'Income Valuation'!C34/('Income Valuation'!C59*(1+'Income Valuation'!C49)+'Income Valuation'!C39*'Income Valuation'!C65-'Income Valuation'!C65)
B26: Read | D26: Downside stresses NOI −8%, exit cap +50 bps, and rate +75 bps simultaneously (a compound recession case). The base case is highlighted; the levered IRR range brackets the deal for the investment committee.

Sheet Assemblage
B1: THE ASSEMBLAGE · COVERED LAND PLAY
B2: E Sunrise Blvd @ the Galleria — five contiguous assets, plat block 49-42-36-12 · buy the income, control the dirt · highest & best use = hold for Live Local density
B4: THE COVERED-LAND THESIS
B5: Assemble the whole E Sunrise Blvd frontage at the Galleria hard corner. Each asset is bought/valued off the rent it produces;
B6: the in-place income covers the carry (debt service, taxes, insurance) while DAWN RE controls ~7+ acres for eventual redevelopment.
B7: Redevelopment does NOT pencil today (AE flood zone, coastal hard costs → negative residual), so the play is to HOLD the income-
B8: covered land and hold the Live Local density option. Publix already proved the model — it paid land value ($679/SF bldg), not income value.
B10: ASSET ROLL-UP — 🟢 green = live links to each asset tab
B11: Asset | C11: Control cost | D11: In-place NOI | E11: Going-in cap | F11: Land SF | G11: Land value | H11: Unlev IRR | I11: Lev IRR | J11: Note
B12: Shahidi Retail (Galleria Plaza) | C12: ='Shahidi Retail'!C57 | D12: ='Shahidi Retail'!C122 | E12: =D12/C12 | F12: ='Shahidi Retail'!C36 | G12: ='Shahidi Retail'!C80 | H12: ='Shahidi Retail'!C117 | I12: ='Shahidi Retail'!C120 | J12: acquirable · value-add lease-up
B13: Publix + Starbucks | C13: ='Publix & Starbucks'!C44 | D13: ='Publix & Starbucks'!C109 | E13: =D13/C13 | F13: ='Publix & Starbucks'!C25 | G13: ='Publix & Starbucks'!C67 | H13: ='Publix & Starbucks'!C104 | I13: ='Publix & Starbucks'!C107 | J13: sale-leaseback · acquire fee, lease back
B14: Sunrise Plaza (Kar Luen) | C14: ='Sunrise Plaza'!C47 | D14: ='Sunrise Plaza'!C112 | E14: =D14/C14 | F14: ='Sunrise Plaza'!C28 | G14: ='Sunrise Plaza'!C70 | H14: ='Sunrise Plaza'!C107 | I14: ='Sunrise Plaza'!C110 | J14: acquirable · restaurant value-add
B15: Galleria Corporate Centre (office) | C15: ='Office Condo'!I97 | D15: ='Office Condo'!C78 | E15: =D15/C15 | F15: 0 | G15: =0 | H15: ='Office Condo'!C73 | I15: ='Office Condo'!C76 | J15: buy out both condo owners
B16: 1040 Bayview (covered land) | C16: ='Land'!E40 | D16: ='Land'!C47 | E16: =D16/C16 | F16: ='Land'!C15 | G16: ='Land'!E40 | H16: ='Land'!C65 | I16: ='Land'!C68 | J16: entitled 259 units · hold for redevelopment
B17: ASSEMBLAGE TOTAL (pre-premium) | C17: =SUM(C12:C16) | D17: =SUM(D12:D16) | E17: =D17/C17 | F17: =SUM(F12:F16) | G17: =SUM(G12:G16) | H17: — | I17: — | J17: blended going-in cap covers carry
B19: COVERED-LAND METRICS & ACQUISITION COST
B20: Total existing building (GLA, SF) | C20: =341501 | D20: existing improvements across all five
B21: Total land assembled (acres) | C21: =F17/43560 | D21: ≈ 7+ acres of E Sunrise frontage
B22: Blended land basis ($/SF) | C22: =G17/F17 | D22: vs. subject comps $228–255/SF; Galleria bulk $53/SF
B23: Blended in-place cap (income ÷ cost) | C23: =D17/C17 | D23: covered-land range ~3–5% — income covers carry, not a yield play
B25: Assemblage premium (to control holdouts)
B26: Low | C26: =C17*(1+'Assumptions'!C27) | D26: ='Assumptions'!C27
B27: Base | C27: =C17*(1+'Assumptions'!C28) | D27: ='Assumptions'!C28
B28: High | C28: =C17*(1+'Assumptions'!C29) | D28: ='Assumptions'!C29
B29: TOTAL ASSEMBLAGE ACQUISITION COST (base) | C29: =C27 | D29: 🔶 base premium (Assumptions tab) on the summed control cost
B31: HIGHEST & BEST USE — redevelopment residual (Live Local) vs. hold
B32: Redevelopment residual — 1040 Bayview (per Land tab) | C32: ='Land'!C78
B33: Redevelopment verdict | C33: HOLD | D33: Residual runs NEGATIVE in the AE flood zone at current coastal hard costs — do not force it positive. Best use today = hold the income-covered land + Live Local density option until costs/rents support redevelopment.
B35: PORTFOLIO CAPITAL — consolidated returns computed on the Income Valuation tab
B36: Total equity required (all assets, at asset prices) | C36: ='Shahidi Retail'!C78+'Publix & Starbucks'!C65+'Sunrise Plaza'!C68+'Office Condo'!C46+'Land'!C52
B37: Total in-place NOI (covers carry) | C37: =D17
B38: Portfolio IRR (unlevered / levered) | D38: Computed from the CONSOLIDATED cash flows on the Income Valuation tab — never by averaging asset IRRs (mathematically invalid). See that tab for portfolio returns at both the income and covered-land prices.

Sheet Highest & Best Use
B1: HIGHEST & BEST USE — INDIVIDUAL vs. ASSEMBLED
B2: Every component priced on its own, then combined; the land valued as regular fragmented parcels and as an assembled superblock (worth more, but hard to put together); the office FULL BUY-OUT; and the Live Local redevelopment test.
B4: ① COMPONENT PRICING — each priced independently, then combined (🟢 live links)
B5: Component | C5: Independent price | E5: Basis / note
B6: Shahidi Retail (Galleria Plaza) | C6: ='Shahidi Retail'!C57 | E6: acquire fee · value-add retail
B7: Publix + Starbucks | C7: ='Publix & Starbucks'!C44 | E7: sale-leaseback (acquire fee)
B8: Sunrise Plaza (Kar Luen) | C8: ='Sunrise Plaza'!C47 | E8: acquire fee · restaurant value-add
B9: Galleria Corp Centre (full buy-out) | C9: ='Office Condo'!I97 | E9: buy out BOTH condo owners
B10: 1040 Bayview (entitled land) | C10: ='Land'!E40 | E10: covered land · hold for redevelopment
B11: SUM OF THE PARTS (priced independently) | C11: =SUM(C6:C10) | E11: what you'd pay buying each one at a time
B12: ＋ Assemblage premium (hard to put together) | C12: =C11*'Assumptions'!C28 | D12: ='Assumptions'!C28 | E12: 5 owners · a sale-leaseback · a fractured condo · holdout risk
B13: PRICED AS AN ASSEMBLAGE (base) | C13: =C11+C12 | E13: total to control the whole block
B15: ACQUISITION HISTORY — what each owner paid, and when (seller basis = negotiation leverage)
B16: Component / owner | C16: Bought | D16: For | E16: Our modeled price | F16: note
B17: Shahidi Retail — Shawnick Galleria LLC (Shahidi) | C17: 11/09/2021 | D17: 17100000 | E17: ='Shahidi Retail'!C57 | F17: Special Warranty Deed (flagged disqualified sale)
B18: Publix + Starbucks — REAL SUB LLC (Publix) | C18: 03/14/2025 | D18: 25000000 | E18: ='Publix & Starbucks'!C44 | F18: Trustee's Deed · $679/SF bldg
B19: Sunrise Plaza — Kar Luen Inc | C19: Oct 2000 | D19: 128000 | E19: ='Sunrise Plaza'!C47 | F19: stale/nominal — held since; no recent arm's-length
B20: Office — Main St Fund LLC (57.4%) | C20: 09/23/2019 | D20: 10000000 | E20: ='Office Condo'!I90 | F20: 96,930 SF + 2 parking lots (Daily Business Review)
B21: Office — Intl Sunrise Partners (42.6%) | C21: 2011 | D21: — | E21: ='Office Condo'!I91 | F21: condo-conversion sponsor (Bush Development)
B22: 1040 Bayview — Sunrise & Bayview Partners | C22: 2014 (JV) | D22: — | E22: ='Land'!E40 | F22: Procacci; BBX exited 2022; stale 1961 deed $801,933
B24: ② LAND VALUE — as REGULAR (fragmented) parcels
B25: Parcel | C25: Land SF | D25: $/SF | E25: Land value | F25: note
B26: Shahidi Retail | C26: ='Shahidi Retail'!C36 | D26: ='Shahidi Retail'!C79 | E26: ='Shahidi Retail'!C80 | F26: standalone parcel
B27: Publix + Starbucks | C27: ='Publix & Starbucks'!C25 | D27: ='Publix & Starbucks'!C55 | E27: ='Publix & Starbucks'!C67 | F27: standalone parcel
B28: Sunrise Plaza (Kar Luen) | C28: ='Sunrise Plaza'!C28 | D28: ='Sunrise Plaza'!C58 | E28: ='Sunrise Plaza'!C70 | F28: standalone parcel
B29: 1040 Bayview | C29: ='Land'!C15 | D29: ='Land'!E40/'Land'!C15 | E29: ='Land'!E40 | F29: standalone parcel
B30: SUM OF THE PARTS (fragmented land) | C30: =SUM(C26:C29) | D30: =SUM(E26:E29)/SUM(C26:C29) | E30: =SUM(E26:E29) | F30: office excluded — building, not land (buy-out below)
B31: ② LAND VALUE — as an ASSEMBLED SUPERBLOCK (plottage: worth more, hard to assemble)
B32: Assembled land (SF) | C32: =C30 | E32: 4 contiguous land parcels, one plat block
B33: Assembled land (acres) | C33: =C30/43560
B34: Plottage / assemblage premium (base) | C34: ='Assumptions'!C28 | E34: uplift for a large contiguous development site
B35: Assembled land value — low | C35: =E30*(1+'Assumptions'!C27)
B36: Assembled land value — BASE | C36: =E30*(1+'Assumptions'!C28)
B37: Assembled land value — high | C37: =E30*(1+'Assumptions'!C29)
B38: Implied assembled $/SF (base) | C38: =C36/C30 | E38: vs. fragmented blend above
B39: PLOTTAGE PREMIUM (assembled − fragmented) | C39: =C36-E30 | E39: the value created / cost incurred by assembling the hard-to-put-together block
B40: Entitlement lift (post-Live Local approval) | C40: ='Assumptions'!C32 | E40: value bump once entitled for Live Local density
B41: POST-APPROVAL assembled land value | C41: =C36*(1+'Assumptions'!C32) | E41: what the ENTITLED dirt is worth — the redevelopment upside the premium buys you the option on
B43: ③ OFFICE CONDO — FULL BUY-OUT (the building on the corner, two dominant owners)
B44: Main Street Fund LLC (Grove Gate, 57.4%) | C44: ='Office Condo'!I90 | E44: bought 96,930 SF + 2 parking lots for $10M (2019)
...

Sheet Shahidi Retail
B1: SHAHIDI RETAIL CENTER · “GALLERIA PLAZA”
B2: 2541–2595 E Sunrise Blvd, Fort Lauderdale, FL 33304 | Folio 49-42-36-12-0070 | 26,272 SF NNN neighborhood retail · 83.17% leased · value-add lease-up
B4: PROPERTY FACTS — ✅ public record (BCPA / Sunbiz / recorded deed)
B5: Record owner | D5: SHAWNICK GALLERIA LLC
B6: Principal / manager | D6: Esmail Shahidi (mgr) — Sunbiz L21000389291
B7: Gross leasable area (GLA) | D7: 26,272 SF
B8: Land | D8: 67,080 SF (1.54 ac)
B9: Year built | D9: 1960 (eff. 1980)
B10: Zoning / flood | D10: B-1 (Boulevard Business) / FEMA AE
B11: Last sale | D11: 11/09/2021 — $17,100,000 (Special Warranty Deed)
B12: 2025 real-estate taxes | D12: $162,366 (2024: $152,766)
B13: 2026 just / market value (BCPA) | D13: $8,911,690
B14: Effective millage | D14: 1.91% (2025 tax ÷ just value)
B15: Derived basis on $17.1M | D15: $254.92/SF land · $650.88/SF building
B16: In-place occupancy | D16: 83.17% → ~4,422 SF vacant to lease
B18: TENANT RENT ROLL — 🔶 suites/rents estimated from corridor comps ($45–60/SF NNN); SF-weighted blend ties to model market rent
B19: Suite | C19: Tenant | D19: Category | F19: SF | G19: $/SF NNN | H19: Annual rent | K19: Tenant type
B20: 2541 | C20: Primo Liquors & Fine Wine | D20: Retail – liquor/wine | F20: 4000 | G20: 48 | H20: =F20*G20 | K20: Local
B21: 2577 | C21: Wells Fargo Bank | D21: Bank / financial | F21: 3500 | G21: 62 | H21: =F21*G21 | K21: NATIONAL credit
B22: 2543–75 | C22: In-line shops (mid-strip) | D22: Various local retail/service | F22: 3700 | G22: 52 | H22: =F22*G22 | K22: Local
B23: 2587 | C23: Verizon Wireless | D23: Wireless / electronics | F23: 2200 | G23: 58 | H23: =F23*G23 | K23: NATIONAL credit
B24: 2595 | C24: First Impressions Smile Center | D24: Medical – dentistry | F24: 2200 | G24: 54 | H24: =F24*G24 | K24: Local
B25: 2549 | C25: Freeman's Luggage & Gifts | D25: Retail – luggage/gifts | F25: 2000 | G25: 50 | H25: =F25*G25 | K25: Local
B26: 2583 | C26: Eyes on Sunrise | D26: Medical – optometry | F26: 1800 | G26: 56 | H26: =F26*G26 | K26: Local
B27: 2541 | C27: Lilac & Lilies Boutique | D27: Retail – apparel | F27: 1250 | G27: 58 | H27: =F27*G27 | K27: Local
B28: 2595 | C28: Roxanne Jackson – GEICO | D28: Insurance agency | F28: 1200 | G28: 56 | H28: =F28*G28 | K28: Regional
B29: — | C29: VACANT / available (mid-strip) | D29: Lease-up target to 95% | F29: 4422 | G29: — | H29: — | K29: value-add upside
B30: TOTAL / WEIGHTED AVG | C30: 9 tenants + vacancy | F30: =SUM(F20:F29) | G30: =IFERROR(SUM(H20:H28)/SUM(F20:F28),0) | H30: =SUM(H20:H28) | K30: Wells Fargo + Verizon = credit
B32: ASSUMPTIONS — 🔵 blue = hardcoded inputs (the only cells you change)
B33: Property
B34: GLA (SF) | C34: 26272 | D34: ✅ BCPA
B35: In-place occupancy | C35: ='Assumptions'!C51 | D35: 🟢 Assumptions
B36: Land (SF) | C36: ='Assumptions'!C48 | D36: 🟢 Assumptions
B37: Effective millage | C37: 0.0191 | D37: ✅ 2025 tax ÷ just value
B38: Revenue
B39: In-place base rent ($/SF NNN) | C39: 55 | D39: 🔶 owner says $60; corridor $45–60
B40: Market rent ($/SF NNN) | C40: ='Assumptions'!C50 | D40: 🟢 Assumptions
B41: Market rent growth | C41: 0.03 | D41: 🔶
B42: Stabilized occupancy | C42: ='Assumptions'!C52 | D42: 🟢 Assumptions
B43: Credit & collection loss | C43: 0.02 | D43: 🔶
...

Sheet Publix & Starbucks
B1: PUBLIX + STARBUCKS · SALE-LEASEBACK (acquire fee, lease back during entitlement)
B2: 2501–2519 E Sunrise Blvd | Folio 49-42-36-12-0060 | REAL SUB LLC (Publix) · 36,822 SF · built 2011 · acquire the fee → Publix leases back → rent covers carry while you entitle the land
B4: PROPERTY FACTS — ✅ BCPA / 🔶 SALE-LEASEBACK STRUCTURE (leaseback terms on the Assumptions tab)
B5: Record owner (today) | D5: REAL SUB LLC (Publix Super Markets real-estate entity, Lakeland FL) — fee owner
B6: Deal structure | D6: Sale-leaseback: DAWN RE acquires the fee; Publix leases back and pays rent during the entitlement period, then vacates for redevelopment
B7: Building | D7: 36,822 SF (Publix ~34,622 SF leaseback + Starbucks drive-thru pad ~2,200 SF)
B8: Land | D8: 109,791 SF (2.520 ac)
B9: Year built | D9: 2011 (eff. 2012)
B10: Last sale | D10: 03/14/2025 — $25,000,000 (Trustee's Deed) = $679/SF bldg · $228/SF land
B11: 2025 real-estate taxes | D11: $208,467 (2024: $217,404) — NNN, reimbursed by Publix during leaseback
B12: Leaseback economics | D12: Publix leaseback ~$22/SF NNN (bridge rate) + Starbucks pad ~$60/SF NNN; ~4-yr term (adjustable on Assumptions tab)
B13: Covered-land logic | D13: The leaseback rent covers the operating carry (Publix pays taxes/ins NNN) while the land is entitled; the play is the dirt, not the current yield
B14: Standalone return (below) | D14: NEGATIVE on a pure income basis by design — you pay land value ($25M) for income supporting only ~$13M. The return is the LAND, realized via the assemblage / redevelopment; the leaseback (DSCR ≈ 1.0x) simply covers the entitlement carry
B16: RENT ROLL — 🔶 sale-leaseback terms (set on the Assumptions tab · Publix block)
B17: Tenant / component | E17: Category | G17: SF | H17: $/SF NNN | I17: Annual rent | L17: Note
B18: Publix (sale-leaseback) | E18: Grocery anchor (credit) — leases back during entitlement | G18: 34622 | H18: 22 | I18: =G18*H18 | L18: leaseback NNN; terms on Assumptions tab
B19: Starbucks (drive-thru pad) | E19: QSR pad (credit) | G19: 2200 | H19: 60 | I19: =G19*H19 | L19: pad NNN; terms on Assumptions tab
B20: TOTAL / WTD AVG | G20: =SUM(G18:G19) | H20: =IFERROR(SUM(I18:I19)/SUM(G18:G19),0) | I20: =SUM(I18:I19) | L20: 100% occ · credit tenants · sale-leaseback
B22: ASSUMPTIONS — 🔵 blue = hardcoded inputs
B23: Property & revenue
B24: Rentable SF | C24: 36822 | D24: ✅ BCPA (36,822 SF)
B25: Land (SF) | C25: ='Assumptions'!C64 | D25: 🟢 Assumptions
B26: In-place occupancy | C26: ='Assumptions'!C71 | D26: 🟢 Assumptions
B27: Stabilized occupancy | C27: ='Assumptions'!C72 | D27: 🟢 Assumptions
B28: Blended NNN rent ($/SF) — leaseback + pad | C28: =('Assumptions'!C67*'Assumptions'!C66+'Assumptions'!C69*'Assumptions'!C68)/C24 | D28: 🟢 computed from Publix leaseback + Starbucks pad (Assumptions)
B29: Rent growth | C29: 0.02 | D29: 🔶
B30: Credit & collection loss | C30: 0.01 | D30: 🔶
B31: Effective millage | C31: 0.0191 | D31: ✅ 2025
B32: Operating expenses
B33: Insurance ($/yr) | C33: ='Assumptions'!C73 | D33: 🟢 Assumptions
B34: CAM ($/yr, recoverable) | C34: ='Assumptions'!C74 | D34: 🟢 Assumptions
B35: Repairs & maintenance ($/yr) | C35: ='Assumptions'!C75 | D35: 🟢 Assumptions
B36: Management fee (% EGR) | C36: ='Assumptions'!C76 | D36: 🟢 Assumptions
B37: Expense growth | C37: 0.03 | D37: 🔶
B38: Capital
B39: Tenant improvements ($/SF) | C39: 0 | D39: 🔶 on leased-up SF
B40: Leasing commissions ($/SF) | C40: 0 | D40: 🔶 on leased-up SF
B41: Replacement reserves ($/SF/yr) | C41: 0.15 | D41: 🔶
B42: Rollover leasing reserve ($/SF/yr) | C42: 0.15 | D42: 🔶
B43: Acquisition & financing
...

Sheet Sunrise Plaza
B1: SUNRISE PLAZA · ADJACENT RETAIL CENTER (2465–2485, incl. 2473)
B2: 2465–2485 E Sunrise Blvd | Folio 49-42-36-12-0011 | Kar Luen Inc · 25,105 SF · built 1962 (remod. 1987) · SEPARATE parcel from the 2455 office condo · restaurant/jeweler value-add
B4: PROPERTY FACTS — ⚠️ REPORTED (BCPA blocked in build env; LoopNet/Sunbiz sourced)
B5: Record owner | D5: Kar Luen Inc (FL corp est. 1994; registered at 2465 E Sunrise)
B6: Parcel scope | D6: 2465 / 2473 / 2485 E Sunrise — one folio (-0011); DISTINCT from the 2455 office condo (its own tab)
B7: Building | D7: 25,105 SF, 2-story retail/commercial
B8: Land | D8: 0.71 ac ≈ 30,928 SF
B9: Year built | D9: 1962 (remodeled 1987)
B10: Zoning | D10: Community Business (CB) / B-1 corridor
B11: Anchor tenant | D11: Daoud's Fine Jewelry — 100+ yr family jeweler at 2473 (~6,000 SF)
B12: Reported value | D12: ≈ $8.5M (UNVERIFIED — no recent arm's-length sale)
B13: Last recorded sale | D13: Oct 2000 — $128,000 (stale/partial; not a value indicator)
B15: RENT ROLL (2465–2485 E Sunrise, incl. 2473) — 🔶 tenants REPORTED (Yelp/LoopNet); suite SF & rents estimated
B16: Tenant / component | E16: Category | G16: SF | H16: $/SF NNN | I16: Annual rent | L16: Note
B17: 2473 · Daoud's Fine Jewelry | E17: Retail – jeweler (anchor) | G17: 6000 | H17: 34 | I17: =G17*H17 | L17: 100+ yr family business
B18: 2465 · Sunness Supper Club | E18: Restaurant | G18: 4000 | H18: 36 | I18: =G18*H18 | L18: corner restaurant
B19: 2475 · BurgerFi | E19: Fast-casual restaurant | G19: 3000 | H19: 40 | I19: =G19*H19 | L19: national franchise
B20: 2485 · In-line shops | E20: Various local retail/service | G20: 6005 | H20: 30 | I20: =G20*H20 | L20: balance of occupied
B21: 2481 · SFL Maven | E21: Retail / resale | G21: 1100 | H21: 32 | I21: =G21*H21 | L21: small-shop
B22: VACANT / available | E22: Lease-up upside | G22: 5000 | H22: — | I22: — | L22: value-add
B23: TOTAL / WTD AVG | G23: =SUM(G17:G22) | H23: =IFERROR(SUM(I17:I21)/SUM(G17:G21),0) | I23: =SUM(I17:I21) | L23: Daoud's = anchor; ~20% vacant
B25: ASSUMPTIONS — 🔵 blue = hardcoded inputs
B26: Property & revenue
B27: Rentable SF | C27: 25105 | D27: ⚠️ LoopNet (25,105 SF)
B28: Land (SF) | C28: ='Assumptions'!C84 | D28: 🟢 Assumptions
B29: In-place occupancy | C29: ='Assumptions'!C87 | D29: 🟢 Assumptions
B30: Stabilized occupancy | C30: ='Assumptions'!C88 | D30: 🟢 Assumptions
B31: Market rent ($/SF NNN) | C31: ='Assumptions'!C86 | D31: 🟢 Assumptions
B32: Rent growth | C32: 0.03 | D32: 🔶
B33: Credit & collection loss | C33: 0.03 | D33: 🔶
B34: Effective millage | C34: 0.0191 | D34: ✅ 2025 area millage
B35: Operating expenses
B36: Insurance ($/yr) | C36: ='Assumptions'!C89 | D36: 🟢 Assumptions
B37: CAM ($/yr, recoverable) | C37: ='Assumptions'!C90 | D37: 🟢 Assumptions
B38: Repairs & maintenance ($/yr) | C38: ='Assumptions'!C91 | D38: 🟢 Assumptions
B39: Management fee (% EGR) | C39: ='Assumptions'!C92 | D39: 🟢 Assumptions
B40: Expense growth | C40: 0.03 | D40: 🔶
B41: Capital
B42: Tenant improvements ($/SF) | C42: 30 | D42: 🔶 on leased-up SF
B43: Leasing commissions ($/SF) | C43: 20 | D43: 🔶 on leased-up SF
...

Sheet Office Condo
B1: GALLERIA CORPORATE CENTRE · OFFICE CONDOMINIUM
B2: 2455 E Sunrise Blvd | 13-story Class B office condo · ~168,807 SF · built 1973 (renov. 2007) · fractured ownership — every owner modeled individually + full buy-out
B4: PROPERTY FACTS — ⚠️ REPORTED (LoopNet / Daily Business Review / Sunbiz; BCPA blocked in build env)
B5: Building | D5: ~168,807 SF, 13-story Class B office condominium (+ ground-floor retail)
B6: Year built / reno | D6: 1973 (renovated 2007)
B7: Condo regime | D7: Created 2007; converted to condos 2011 by Bush Development Group
B8: Association | D8: Galleria Corporate Centre Condominium Association, Inc. (Sunbiz N07000001902)
B9: Lease economics | D9: Office units leased ≈ $26/SF Modified Gross
B10: Sale comp (historical) | D10: Unit sales ≈ $300/SF (pre-2020; office values since softened)
B11: Amenities | D11: Covered/valet parking, concierge, on-site café, two conference facilities
B12: Ownership | D12: Fractured condo: Main St Fund (Grove Gate) held 57.4% and is NOW RESELLING units individually; the balance is International Sunrise + a growing number of small owners (Jorgensen, Hublot, Merrimac, individual suites)
B13: Buy-out note | D13: Assembling the building = buying out EVERY unit owner (modeled individually below; the un-itemizable balance is grouped)
B14: ⚠️ BCPA limitation | D14: bcpa.net and the Broward Clerk are egress-blocked in this build; the complete per-unit folio roster (every unit, owner, price, date) needs a direct BCPA pull to finish
B16: ASSUMPTIONS — 🔵 blue = hardcoded inputs (Modified-Gross office)
B17: Rentable SF (both owners) | C17: 168807 | D17: ⚠️ ~168,807 SF
B18: In-place occupancy | C18: ='Assumptions'!C101 | D18: 🟢 Assumptions
B19: Stabilized occupancy | C19: ='Assumptions'!C102 | D19: 🟢 Assumptions
B20: Market rent ($/SF Modified Gross) | C20: ='Assumptions'!C100 | D20: 🟢 Assumptions
B21: Rent growth | C21: 0.03 | D21: 🔶
B22: Credit & vacancy loss | C22: 0.03 | D22: 🔶
B23: Effective millage | C23: 0.0191 | D23: ✅ area millage
B24: Office opex ex-taxes ($/SF, landlord) | C24: ='Assumptions'!C103 | D24: 🟢 Assumptions
B25: Management fee (% EGR) | C25: ='Assumptions'!C104 | D25: 🟢 Assumptions
B26: Expense growth | C26: 0.03 | D26: 🔶
B27: Replacement reserves ($/SF/yr) | C27: 0.2 | D27: 🔶
B28: Acquisition basis (income value) | C28: ='Assumptions'!C99 | D28: 🟢 Assumptions
B29: Closing & acq costs (% price) | C29: 0.02 | D29: 🔶
B30: Senior loan LTV | C30: ='Assumptions'!C107 | D30: 🟢 Assumptions
B31: Senior loan rate | C31: ='Assumptions'!C108 | D31: 🟢 Assumptions
B32: Amortization (yrs) | C32: 30 | D32: 🔶
B33: Going-in cap | C33: ='Assumptions'!C105 | D33: 🟢 Assumptions
B34: Exit cap | C34: ='Assumptions'!C106 | D34: 🟢 Assumptions
B35: Cost of sale | C35: 0.02 | D35: 🔶
B36: Hold period (yrs) | C36: 5 | D36: 🔶
B37: Discount rate (NPV) | C37: 0.1 | D37: 🔶
B38: Sale comp ($/SF) | C38: 300 | D38: ⚠️ historical ~$300/SF
B40: DERIVED VALUES & DEBT SIZING
B41: Senior loan amount | C41: =C28*C30 | D41: price × LTV
B42: Monthly rate | C42: =C31/12
B43: Annual debt service | C43: =C41*(C42/(1-(1+C42)^(-C32*12)))*12
...

Sheet Land
B1: 1040 BAYVIEW · COVERED-LAND / REDEVELOPMENT SITE
B2: 1040 Bayview Dr | Folio 49-42-36-12-0040 | Sunrise & Bayview Partners LLC (Procacci) · 2.39 ac · existing 84,495 SF office (1967) · entitled 259 units
B4: PROPERTY FACTS — ⚠️ REPORTED (LoopNet / Florida YIMBY / BBX / Procacci; BCPA blocked in build env)
B5: Record owner | D5: Sunrise and Bayview Partners, LLC (Procacci Development affiliate; BBX exited 2022)
B6: Land | D6: 2.39 ac ≈ 104,108 SF — same plat block (49-42-36-12) as the assemblage
B7: Existing improvement | D7: 84,495 SF office building (built 1967) — a redevelopment site, not raw land
B8: Zoning | D8: B-1 (Boulevard Business) / CB core commercial; active rezoning UDP-Z25002
B9: Entitlement | D9: “The Residences at Bayview” — 259 units + 8,081 SF commercial, 8-story (81 ft)
B10: BCPA market value | D10: ≈ $6,685,580 (reported)
B11: Status | D11: NOT listed — owner is entitling, not selling; a future assemblage/JV target
B12: Covered-land thesis | D12: Interim office income covers carry; value is the entitled land + Live Local density optionality
B14: ASSUMPTIONS — 🔵 blue = hardcoded inputs
B15: Land (SF) | C15: 104108 | D15: ⚠️ 2.39 ac
B16: Existing office SF | C16: 84495 | D16: ⚠️ 1967 bldg
B17: Entitled units | C17: 259 | D17: ⚠️ approved 259
B18: BCPA market value | C18: 6685580 | D18: ⚠️ reported
B19: Interim office occupancy | C19: ='Assumptions'!C112 | D19: 🟢 Assumptions
B20: Interim office rent ($/SF MG) | C20: ='Assumptions'!C113 | D20: 🟢 Assumptions
B21: Interim office opex ($/SF) | C21: ='Assumptions'!C114 | D21: 🟢 Assumptions
B22: Management fee (% EGR) | C22: ='Assumptions'!C115 | D22: 🟢 Assumptions
B23: Effective millage | C23: 0.0191 | D23: ✅ area
B24: Acquisition basis (entitled land) | C24: ='Assumptions'!C111 | D24: 🟢 Assumptions
B25: Closing & acq costs (% price) | C25: 0.02 | D25: 🔶
B26: Land value growth | C26: 0.04 | D26: 🔶
B27: Hold period (yrs) | C27: 5 | D27: 🔶 to redevelopment
B28: Land loan LTV (IO) | C28: ='Assumptions'!C116 | D28: 🟢 Assumptions
B29: Land loan rate (IO) | C29: ='Assumptions'!C117 | D29: 🟢 Assumptions
B30: Cost of sale at exit | C30: 0.02 | D30: 🔶
B31: Discount rate (NPV) | C31: 0.1 | D31: 🔶
B32: Expense growth | C32: 0.03 | D32: 🔶
B34: LAND VALUATION — four approaches (Low / Base / High)
B35: Approach | D35: Low | E35: Base | F35: High | G35: Basis / note
B36: ① Per SF of land | D36: =C15*'Assumptions'!C33 | E36: =C15*'Assumptions'!C34 | F36: =C15*'Assumptions'!C35 | G36: land SF × $/SF (low/base/high on Assumptions tab)
B37: ② Per entitled unit | D37: =C17*'Assumptions'!C36 | E37: =C17*'Assumptions'!C37 | F37: =C17*'Assumptions'!C38 | G37: units × $/unit (low/base/high on Assumptions tab)
B38: ③ BCPA market value (floor) | D38: =C18 | E38: =C18 | F38: =C18 | G38: assessed just value — conservative floor
B39: ④ Interim income value | D39: =C48 | E39: =C48 | F39: =C48 | G39: existing office NOI ÷ 8% cap (income the land throws off)
